Workbook

Sheet Products
A1: ProductID | B1: Product | C1: Price
A2: 101 | B2: Product A | C2: 120
A3: 102 | B3: Product B | C3: 150
A4: 103 | B4: Product C | C4: 200
A5: 104 | B5: Product D | C5: 90
A6: 105 | B6: Product E | C6: 220
A7: 106 | B7: Product F | C7: 130

Sheet Orders
A1: 1 | B1: Use VLOOKUP to find the product names for each ProductID in the Orders worksheet.
A2: OrderID | B2: ProductID | C2: Quantity | D2: Product Name
A3: 1 | B3: 101 | C3: 2 | D3: =VLOOKUP(B3,Products!$A$1:$C$7,2,0) -> Product A
A4: 2 | B4: 103 | C4: 1 | D4: =VLOOKUP(B4,Products!$A$1:$C$7,2,0) -> Product C
A5: 3 | B5: 105 | C5: 4 | D5: =VLOOKUP(B5,Products!$A$1:$C$7,2,0) -> Product E
A6: 4 | B6: 106 | C6: 3 | D6: =VLOOKUP(B6,Products!$A$1:$C$7,2,0) -> Product F
A7: 5 | B7: 102 | C7: 5 | D7: =VLOOKUP(B7,Products!$A$1:$C$7,2,0) -> Product B
A8: 6 | B8: 104 | C8: 6 | D8: =VLOOKUP(B8,Products!$A$1:$C$7,2,0) -> Product D
A10: 2 | B10: Use VLOOKUP to find the price for each ProductID in the Orders worksheet, then calculate the TotalPrice by multiplying the Quantity by the Product Price.
A11: OrderID | B11: ProductID | C11: Quantity | D11: Product Name | E11: Price | F11: Total Price
A12: 1 | B12: 101 | C12: 2 | D12: =VLOOKUP(B12,Products!$A$1:$C$7,2,0) -> Product A | E12: =VLOOKUP(Orders!D12,Products!$B$1:$C$7,2,0) -> 120 | F12: =E12*C12 -> 240
A13: 2 | B13: 103 | C13: 1 | D13: =VLOOKUP(B13,Products!$A$1:$C$7,2,0) -> Product C | E13: =VLOOKUP(Orders!D13,Products!$B$1:$C$7,2,0) -> 200 | F13: =E13*C13 -> 200
A14: 3 | B14: 105 | C14: 4 | D14: =VLOOKUP(B14,Products!$A$1:$C$7,2,0) -> Product E | E14: =VLOOKUP(Orders!D14,Products!$B$1:$C$7,2,0) -> 220 | F14: =E14*C14 -> 880
A15: 4 | B15: 106 | C15: 3 | D15: =VLOOKUP(B15,Products!$A$1:$C$7,2,0) -> Product F | E15: =VLOOKUP(Orders!D15,Products!$B$1:$C$7,2,0) -> 130 | F15: =E15*C15 -> 390
A16: 5 | B16: 102 | C16: 5 | D16: =VLOOKUP(B16,Products!$A$1:$C$7,2,0) -> Product B | E16: =VLOOKUP(Orders!D16,Products!$B$1:$C$7,2,0) -> 150 | F16: =E16*C16 -> 750
A17: 6 | B17: 104 | C17: 6 | D17: =VLOOKUP(B17,Products!$A$1:$C$7,2,0) -> Product D | E17: =VLOOKUP(Orders!D17,Products!$B$1:$C$7,2,0) -> 90 | F17: =E17*C17 -> 540
A19: 3 | B19: Use VLOOKUP to check if there are any ProductIDs in the Orders worksheet that do not exist in the Products worksheet.
A20: OrderID | B20: ProductID | C20: Quantity | D20: Product Name | E20: Existance
A21: 1 | B21: 101 | C21: 2 | D21: Product A | E21: =IF(ISNA(VLOOKUP(B21,Products!$A$1:$C$7,2,0)),"No","Yes") -> Yes
A22: 2 | B22: 103 | C22: 1 | D22: Product C | E22: =IF(ISNA(VLOOKUP(B22,Products!$A$1:$C$7,2,0)),"No","Yes") -> Yes
A23: 3 | B23: 105 | C23: 4 | D23: Product E | E23: =IF(ISNA(VLOOKUP(B23,Products!$A$1:$C$7,2,0)),"No","Yes") -> Yes
A24: 4 | B24: 106 | C24: 3 | D24: Product F | E24: =IF(ISNA(VLOOKUP(B24,Products!$A$1:$C$7,2,0)),"No","Yes") -> Yes
A25: 5 | B25: 102 | C25: 5 | D25: Product B | E25: =IF(ISNA(VLOOKUP(B25,Products!$A$1:$C$7,2,0)),"No","Yes") -> Yes
A26: 6 | B26: 104 | C26: 6 | D26: Product D | E26: =IF(ISNA(VLOOKUP(B26,Products!$A$1:$C$7,2,0)),"No","Yes") -> Yes
A27: 7 | B27: 7 | C27: 7 | D27: Product CR | E27: =IF(ISNA(VLOOKUP(B27,Products!$A$1:$C$7,2,0)),"No","Yes") -> No
A29: 4 | B29: Assume a discount of 10% is given on all products. Use VLOOKUP to find the original price and then calculate the discounted price.
A30: OrderID | B30: ProductID | C30: Quantity | D30: Product Name | E30: Price | F30: Total Price | G30: Discounted Price
A31: 1 | B31: 101 | C31: 2 | D31: =VLOOKUP(B31,Products!$A$1:$C$7,2,0) -> Product A | E31: =VLOOKUP(D31,Products!$B$1:$C$7,2,0) -> 120 | F31: =E31*C31 -> 240 | G31: =(E31*C31)*0.9 -> 216
A32: 2 | B32: 103 | C32: 1 | D32: =VLOOKUP(B32,Products!$A$1:$C$7,2,0) -> Product C | E32: =VLOOKUP(D32,Products!$B$1:$C$7,2,0) -> 200 | F32: =E32*C32 -> 200 | G32: =(E32*C32)*0.9 -> 180
A33: 3 | B33: 105 | C33: 4 | D33: =VLOOKUP(B33,Products!$A$1:$C$7,2,0) -> Product E | E33: =VLOOKUP(D33,Products!$B$1:$C$7,2,0) -> 220 | F33: =E33*C33 -> 880 | G33: =(E33*C33)*0.9 -> 792
A34: 4 | B34: 106 | C34: 3 | D34: =VLOOKUP(B34,Products!$A$1:$C$7,2,0) -> Product F | E34: =VLOOKUP(D34,Products!$B$1:$C$7,2,0) -> 130 | F34: =E34*C34 -> 390 | G34: =(E34*C34)*0.9 -> 351
A35: 5 | B35: 102 | C35: 5 | D35: =VLOOKUP(B35,Products!$A$1:$C$7,2,0) -> Product B | E35: =VLOOKUP(D35,Products!$B$1:$C$7,2,0) -> 150 | F35: =E35*C35 -> 750 | G35: =(E35*C35)*0.9 -> 675
A36: 6 | B36: 104 | C36: 6 | D36: =VLOOKUP(B36,Products!$A$1:$C$7,2,0) -> Product D | E36: =VLOOKUP(D36,Products!$B$1:$C$7,2,0) -> 90 | F36: =E36*C36 -> 540 | G36: =(E36*C36)*0.9 -> 486
A38: 5 | B38: Use VLOOKUP to find the price for each ProductID and then calculate the order value. Find the maximum order value from the list.
A39: OrderID | B39: ProductID | C39: Quantity | D39: Product Name | E39: Price | F39: Order Value
A40: 1 | B40: 101 | C40: 2 | D40: =VLOOKUP(B40,Products!$A$1:$C$7,2,0) -> Product A | E40: =VLOOKUP(D40,Products!$B$1:$C$7,2,0) -> 120 | F40: =E40*C40 -> 240 | G40: =IF(F40=MAX($F$40:$F$45),"Maximum","")
A41: 2 | B41: 103 | C41: 1 | D41: =VLOOKUP(B41,Products!$A$1:$C$7,2,0) -> Product C | E41: =VLOOKUP(D41,Products!$B$1:$C$7,2,0) -> 200 | F41: =E41*C41 -> 200 | G41: =IF(F41=MAX($F$40:$F$45),"Maximum","")
A42: 3 | B42: 105 | C42: 4 | D42: =VLOOKUP(B42,Products!$A$1:$C$7,2,0) -> Product E | E42: =VLOOKUP(D42,Products!$B$1:$C$7,2,0) -> 220 | F42: =E42*C42 -> 880 | G42: =IF(F42=MAX($F$40:$F$45),"Maximum","") -> Maximum
A43: 4 | B43: 106 | C43: 3 | D43: =VLOOKUP(B43,Products!$A$1:$C$7,2,0) -> Product F | E43: =VLOOKUP(D43,Products!$B$1:$C$7,2,0) -> 130 | F43: =E43*C43 -> 390 | G43: =IF(F43=MAX($F$40:$F$45),"Maximum","")
A44: 5 | B44: 102 | C44: 5 | D44: =VLOOKUP(B44,Products!$A$1:$C$7,2,0) -> Product B | E44: =VLOOKUP(D44,Products!$B$1:$C$7,2,0) -> 150 | F44: =E44*C44 -> 750 | G44: =IF(F44=MAX($F$40:$F$45),"Maximum","")
...
